Workbook

Sheet All Board Credits & Important U
A1: Credits | D1: Stadiums of all boards
A2: Boards | B2: Available Credits | D2: Australia | E2: Bangladesh | F2: England | G2: India | H2: Italy | I2: Netherlands | J2: Newzealand | K2: Pakistan | L2: Qatar | M2: Scotland | N2: South Africa | O2: Srilanka | P2: UAE | Q2: West Indies | R2: Zimbabwe | S2: Canada
A3: Scotland | B3: =Scotland!A4 -> 17724615 | D3: {=Australia!B7:B19} -> Level 3 Stadiums | E3: {=Bangladesh!B8:B20} -> Level 3 Stadiums | F3: {=England!B10:B28} -> Level 3 Stadiums | G3: {=India!B7:B16} -> Level 3 Stadiums | H3: {=Italy!B7:B15} -> Level 3 Stadiums | I3: {=Netherlands!B7:B17} -> Level 3 Stadiums | J3: {=Newzealand!B8:B19} -> Level 3 Stadiums | K3: {=Pakistan!B7:B19} -> Level 3 Stadiums | L3: {=Qatar!B8:B19} -> Level 3 Stadiums | M3: {=Scotland!C7:C18} -> Level 3 Stadiums | N3: {=SA!B9:B20} -> Level 3 Stadiums | O3: {=Srilanka!B7:B18} -> Level 3 Stadiums | P3: {=UAE!B7:B18} -> Level 3 Stadiums | Q3: {=WestIndies!B8:B21} -> Level 3 Stadiums | R3: {=Zimbabwe!C7:C19} -> Level 3 Stadiums | S3: {=Canada!B7:B18} -> Level 3 Stadiums
A4: Australia | B4: =Australia!A4 -> 6851560 | D4: Melbourne Cricket Ground | E4: Padma - Meghna Cricket Arena | F4: Lords International Stadium | G4: Eternal Coliseum | H4: Vivian Richards Cricket Ground | I4: Maya Stadium Amsterdam | J4: Eden Park | K4: Pindi International Stadium | L4: West End Park | M4: Grange Cricket Stadium | N4: Newlands Cricket Stadium | O4: Colombo International Stadium | P4: Dubai International Stadium | Q4: ABD Georgetown Cricket Arena | R4: Mosi-oa-Tunya ICS | S4: CAA Centre
A5: Newzealand | B5: =Newzealand!A5 -> 4298385 | D5: Sydney Cricket Ground | E5: Hilsha Heritage Stadium | Franchise League L1 | Upgraded | F5: WGG International Stadium | G5: Sree Padmanaba Cricket Park | H5: Ovale di Carteria | I5: Dutch Cricket Arena Hague | J5: Sky International Stadium | K5: Karachi International Stadium | L5: Lusail International Stadium | M5: Seven Oaks Stadium | N5: Wanderers International Stadium | O5: Kandy International Stadium | P5: Level 2 Stadiums | Q5: Malayalipuram International Stadium | R5: Lachit Borphukan Cricket Stadium | S5: Level 2 Stadiums
A6: Bangladesh | B6: =Bangladesh!A5 -> 5510745 | D6: Optus Stadium | Free T20 WC | E6: Karnaphuli Cricket Park | F6: The Rose Bowl | G6: Jannat Wadi | Franchise League L1 | Upgraded | H6: Level 2 Stadiums | I6: Zubeen Garg Heritage Stadium | J6: Sovereign Crown Arena | K6: Gaddafi Stadium Lahore | Franchise League L1 | Upgraded | L6: Doha International Stadium | M6: Scotba Cricket Stadium | L1 FL | UP | N6: Level 2 Stadiums | O6: Level 2 Stadiums | P6: None | Q6: Bridgetown Royal Cricket Arena | Franchise League L1 | Upgraded | R6: Level 2 Stadiums | S6: None
A7: India | B7: =India!A4 -> 3852710 | D7: Adelaide Oval | E7: Mango Fortress Stadium | F7: Trent Bridge | Franchise League L1 | Upgraded | G7: Level 2 Stadiums | H7: None | I7: Pragjyotish Ground | J7: Thunder Dome | K7: Multan International Stadium | L7: Level 2 Stadiums | M7: K.M Cricket Arena | N7: None | O7: None | P7: Level 1 Stadiums | Q7: Basseterre Patriots Cricket Ground | R7: None | S7: Level 1 Stadiums
A8: Pakistan | B8: =Pakistan!A4 -> 6798500 | D8: Sydney Show Ground | Franchise League L1 | Upgraded | E8: Sylhet Jewel Stadium | F8: The Oval | G8: None | H8: Level 1 Stadiums | I8: Nilachal Khel Pathar | J8: Inferno Bay Arena | K8: Hyder Cricket Stadium | L8: None | M8: Level 2 Stadiums | N8: Level 1 Stadiums | O8: Level 1 Stadiums | P8: None | Q8: Kingstown Volcano Cricket Stdaium | R8: Level 1 Stadiums | S8: None
A9: England | B9: =England!A7 -> 3834985 | D9: Marvel Cricket Stadium | E9: Sundarbans Cricket Fortress | F9: Old Trafford | G9: Level 1 Stadiums | H9: None | I9: Level 2 Stadiums | J9: Ironhold Park | K9: Quetta Cricket Arena | L9: Level 1 Stadiums | M9: None | N9: None | O9: None | Q9: Port of Spain Knights Arena | R9: None
A10: Srilanka | B10: =Srilanka!A4 -> 1654300 | D10: The Gabba | E10: Sonar Bangla Cricket Arena | F10: Yorkshire Headingley | G10: Prince's Arena | I10: None | J10: Alpine Crown Arena | K10: Karakoram Stadium Skardu | L10: None | M10: Level 1 Stadiums | Q10: Kingston Kings Cricket Stadium
A11: Qatar | B11: =Qatar!A5 -> 5621460 | D11: Ninja Stadium Hobart | E11: Sands cox's Bazar | F11: Somerset County Ground | G11: Lion's Citadel | I11: Level 1 Stadiums | J11: Titan Bay Coliseum | Franchise League L1 | Ugraded | K11: Khyber Stadium Peshawar | M11: None | Q11: St. John's Falcon Cricket Arena
A12: West Indies | B12: =WestIndies!A5 -> 6625225 | D12: Level 2 Stadiums | E12: Level 2 Stadiums | F12: Level 2 Stadiums | G12: Master's Arena | I12: None | J12: Level 2 Stadiums | K12: Level 2 Stadiums | Q12: Hayley Matthews IS
A13: Italy | B13: =Italy!A4 -> 1781475 | D13: None | E13: None | F13: Middlesex Lords County Cricket Ground | J13: None | K13: None | Q13: Level 2 Stadiums
A14: Netherlands | B14: =Netherlands!A4 -> 1087315 | D14: Level 1 Stadiums | E14: Level 1 Stadiums | F14: Durahm Riverside Ground | J14: Level 1 Stadiums | K14: Level 1 Stadiums | N14: Sponsors | Q14: None
A15: South Africa | B15: =SA!A6 -> 5181100 | D15: None | E15: None | F15: Level 1 Stadiums | K15: None | Q15: Level 1 Stadiums
A16: UAE | B16: =UAE!A4 -> 468725 | F16: None | Q16: None
A17: Canada | B17: =Zimbabwe!A4 -> 139000
A18: Zimbabwe | B18: =Canada!A4 -> 251500
A19: Ireland | B19: =Ireland!A5 -> 718775
A20: Uganda | B20: =Uganda!A4 -> 174825
A21: USA | B21: =USA!A4 -> 944725
A22: Argentina | B22: ='Dismantled Argentina'!A4 -> 33500
A23: Kenya | B23: =Kenya!A4 -> 127000 | F23: Franchise League Updates
A24: Nepal | B24: =Nepal!A5 -> 164000 | F24: League Name | G24: Award Name | H24: Award Winner | I24: Franchise Team | J24: National Board
A25: Papua New Guinea | B25: =PNG!A4 -> 253225 | F25: THE HUNDRED 2026 | G25: Emerging Player | H25: Vishnu CV | I25: Southern Brave | J25: England
A26: Portugal | B26: =Portugal!A4 -> 72000 | G26: Economical Bowler | H26: Waleed Khan | I26: Southern Brave | J26: Afghanistan
G27: Most Sixes | H27: Hasan Musabir | I27: MI London | J27: Newzealand
A28: International Tournament Updates | G28: Best Bowler | H28: Safeer Babu | I28: Sunrisers Leeds | J28: England
A29: Tournament Name | B29: Awards | C29: Award Winners | D29: Official Board | G29: Best Batsman | H29: Nirmal Baishya | I29: Sunrisers Leeds | J29: Netherlands
A30: T20 World CUP 2026 | B30: Most Dot Balls | C30: Toby Joseph | D30: England | G30: Player of the Tournament | H30: Shivaji Prakash | I30: Welsh Fire | J30: India
B31: Most Maidens | C31: Anurag Raj | D31: Australia | G31: Runners Up | H31: Sunrisers Leeds
B32: Best Economy | C32: Virendra | D32: Srilanka | G32: Champions | H32: MI London
B33: Best Bat Average | C33: Bhavin Kumar | D33: Pakistan | F33: PAKISTAN SUPER LEAGUE 2026 | G33: Emerging Player | H33: Wajdan | I33: Lahore Qalandars | J33: Pakistan
B34: Fastest Century | C34: Rejith Mohan | D34: England | G34: Most Sixes | H34: Muhammad Usman | I34: Lahore Qalandars | J34: Pakistan
B35: Fastest Fifty | C35: Diljith Das | D35: England | G35: Best Bowler | H35: Adithya Mahajan | I35: Lahore Qalandars | J35: Afghanistan
B36: Most Fours | C36: Rejith Mohan | D36: England | G36: Best Batsman | H36: Al Ameen | I36: Quetta Gladiators | J36: West Indies
B37: Most Sixes | C37: Hashir | D37: Scotland | G37: Player of the Tournament | H37: Adithya Mahajan | I37: Lahore Qalandars | J37: Afghanistan
B38: Best Bowl Figure | C38: Anshad | D38: Scotland | G38: Fair Play Award | H38: Quetta Gladiators
B39: Highest Individual Score | C39: Sai Naveen | D39: Australia | G39: Runners up | H39: Hyderabad Kings
B40: Fastest Umpire | C40: Nasrullah Kapri | D40: Pakistan | G40: Champions | H40: Lahore Qalandars
...

Sheet IOCF 2.0
A1: Council of Champions | B1: Council of Established | C1: Council of Challengers | D1: Council of Origins
A2: 1. Scotland
A3: 2. England
A4: 3. Qatar
A5: 4. Australia

Sheet All Time Records
A1: CLUB Format
A2: Field | B2: Player Name | C2: Country | D2: Stats
A3: Highest Score By a Player in a Match | B3: Ameen | C3: West Indies | D3: 125
A4: Best Bowling Figure by a Player in a Match | B4: Rahul Suresh | C4: West Indies | D4: 46116
A5: Highest Score By a Team in a Match
A6: Lowest Score by a Team in a Match | B6: Bangladesh | D6: 192
A7: Highest Score chased by a team
A8: Lowest score defened by a team
A10: T10 Format
A11: Field | B11: Player Name | C11: Country | D11: Stats
A12: Highest Score By a Player in a Match | B12: Abhinav Sham | C12: Nepal | D12: 122
A13: Best Bowling Figure by a Player in a Match
A14: Highest Score By a Team in a Match | B14: West Indies | D14: 216
A15: Lowest Score by a Team in a Match
A16: Highest Score chased by a team
A17: Lowest score defened by a team
A19: T20 Format
A20: Field | B20: Player Name | C20: Country | D20: Stats
A21: Highest Score By a Player in a Match | B21: Hrushikesh HD | C21: Newzealand | D21: 217
A22: Best Bowling Figure by a Player in a Match
A23: Highest Score By a Team in a Match | B23: England | D23: 386
A24: Lowest Score by a Team in a Match
A25: Highest Score chased by a team
A26: Lowest score defened by a team
A28: ODI Format
A29: Field | B29: Player Name | C29: Country | D29: Stats
A30: Highest Score By a Player in a Match | B30: Aaiz Khan | C30: Pakistan | D30: 201
A31: Best Bowling Figure by a Player in a Match
A32: Highest Score By a Team in a Match | B32: Qatar | D32: 472
A33: Lowest Score by a Team in a Match
A34: Highest Score chased by a team
A35: Lowest score defened by a team
A37: Test Format
A38: Field | B38: Player Name | C38: Country | D38: Stats
A39: Highest Score By a Player in a Match | B39: Hirak Jyoti | C39: Netherlands | D39: 176
A40: Best Bowling Figure by a Player in a Match
A41: Highest Score By a Team in a Match | B41: South Africa | D41: 351
A42: Lowest Score by a Team in a Match
A43: Highest Score chased by a team
A44: Lowest score defened by a team

Sheet Afghanistan
A1: Board: Afghanistan
A2: Chairman: Waleed Khan | CEO: Umar Khan
A3: Credits left:
A4: =100000+B6+A21+D6+E6+E14+C6 -> 83000
A5: Players | B5: Player trade | C5: Stadium: | D5: International Series: | E5: Whitewash Win: | F5: Trophy Cabinet ( International series)
A6: 1. Maharoof | B6: -20000 | C6: -30000 | D6: 7000 | E6: 1000 | F6: 1. The Golden Cup
A7: 2. Shobha Joseph | B7: 1. Umar (IOCF): 20K | C7: Level 3 Stadiums | D7: 1. Away(West Indies): 7000 (Won) | E7: 1. vs West Indies: 1
A8: 3. Irfan Sohail | C8: Afghan National Sports Complex
A9: 4. Glinson Babu
A10: 5. Saleem Rana
A11: 6. Muhammad Raheel
A12: 7. Nadeem Ahmed
A13: 8. Adnan Abbas | E13: Whitewash lose:
A14: 9. Abdullah Usmani | E14: 0
A15: 10. Farhan Mallick
A16: 11. Nabahan
A17: 12. Talha Arain
A18: 13. Anoop
A19: 14. Saif Ali
A20: All Franchise League Credits Updates :
A21: =A23 -> 25000
A22: Qatar Elite Crown League :
A23: =A26 -> 25000
A24: 2026
A25: All Team Profit:
A26: =A29+B29+C29+D29+E29+F29+G29+H29 -> 25000
A27: AL KHOR PREDATORS | B27: AL RAYYAN RAIDERS | C27: AL WAKRAH DUKES | D27: DOHA STALLIONS | E27: LUSAIL KNIGHTS | F27: MESAEID BLAZE | G27: QATAR VENOMS | H27: UMM SALAL SPARTANS
A28: Team Profit: | B28: Team Profit: | C28: Team Profit: | D28: Team Profit: | E28: Team Profit: | F28: Team Profit: | G28: Team Profit: | H28: Team Profit:
A29: 0 | B29: 0 | C29: 0 | D29: 0 | E29: 0 | F29: 25000 | G29: 0 | H29: 0
F30: 1. Waleed Khan
F31: No Salary(Traded)
F32: Man of the match: 2 (10000)
F33: Best Bowler: 1 (5000)

Sheet Dismantled Argentina
A1: Board: ARGENTINA
A2: Chairman: Sayandeep Ghosh | CEO: ---
A3: Credits left:
A4: =100000+B6+C6+D6+F6+F11 -> 33500
A5: Players | B5: Player trade | C5: Stadium: | D5: International Series: | E5: Trophy Cabinet ( International Series) | F5: Whitewash Win:
A6: 1. Alidad | B6: =-25000 -> -25000 | C6: -30000 | D6: -11000 | F6: 0
A7: 2. Anik Mukherjee | B7: Anik from USA: 3000 | C7: Level 3 Stadiums | D7: 1. Home(Portugal): 3000 bet (Lost)
A8: 3. Aryan Das | B8: Ibrahim from USA: 3000 | C8: LA GUERRERO Cricket Stadium | D8: 2. Away(Kenya): 3000 bet (Lost)
A9: 4. Bijoy DS | B9: Bijoy from USA: 3000 | D9: 3. Home(Japan): 5000 bet (Lost)
A10: 5. Bilal | B10: Shad from USA: 3000 | F10: Whitewash loss:
A11: 6. Ibrahim Shihab | B11: Jayesh from USA: 3000 | F11: -500
A12: 7. Jayesh Nikije | B12: Kuldeep from PNG: 10000 | F12: 1. The Gaucho-Samurai Trophy(Home)
A13: 8. Wali Muhammad
A14: 9. Sarwar Kapri
A15: 10. Shad Mahar
A16: 11. Shafa Bewas
A17: 12. Raj

Sheet Australia
A1: Board: AUSTRALIA
A2: Chairman: Arnab Sarkar | Ceo: Keshav Shah
A3: Credits left:
A4: =100000+B6+C6+D6+D14+F6+G6+H6+I6+A65+L6+R6+O6 -> 6851560
A5: Players | B5: Stadium: | C5: International Series: | D5: Whitewash: | E5: Trophy Cabinet ( International series) | F5: Traded Players: | G5: IOCF T20 WORLD CUP 🏆: | H5: Player limit exceeded: -20000 | I5: IOCF WORLD TEST CHAMPIONSHIP 🏆: | L5: CONTINENTAL CUP 2026 🏆: ( OCEANIA ) | O5: ODI WORLD CUP 2026 🏆: | R5: Umpires Credits :
A6: 1. Abrar Ali | B6: -190000 | C6: 22000 | D6: 6000 | E6: 1. Kangaroo Protea Cup ( Home ) | F6: 268000 | G6: 15300 | H6: -10000 | I6: =I8+J8+K8 -> 44000 | L6: =L8 -> 431200 | O6: =O8 -> 1144000 | R6: =U10+U19+U33+U36+U50+U55+U62+U65+U76+U82+U55 -> 523250
A7: 2. Adil Rahman | B7: Level 3 Stadiums | C7: Home( Pakistan ): 5000 bet ( Lost ) | D7: Against South Africa: 1 | E7: 2. Caribbean Tri Nation Series ( Away ) | F7: 1. Yasin Iqbal - 5k | G7: Hosting Rights: -42000 | H7: 1. 20 to 25: 10000 | I7: Player Awards | J7: Match Bet Credits | K7: Entry Credits | L7: Players & Match Awards | O7: Players & Match Awards | R7: Umpire | S7: Details | T7: Total Matches | U7: Credits | V7: Points
A8: 3. Alapan Das | B8: Melbourne Cricket Ground | C8: Home( South Africa): 5000 bet ( Won ) | D8: Against Afghanistan: 1 | E8: 3. Aus Afg Power series ( Home ) | F8: 2. Karan Kumar - 5k | G8: Entry: -5000 | I8: =K27+K30+K33+K36+K39+K42+K45+K48 -> 19000 | J8: 30000 | K8: -5000 | L8: =N10+N11+N14+N15+N20+N23+N25+N26+N27 -> 431200 | O8: =Q10+Q14+Q15+Q17+Q19+Q20+Q22+Q23 -> 1144000 | R8: 1. Yasin Iqbal | S8: Club Series | T8: 16 | U8: =T8*1000 -> 16000 | V8: =T8*20 -> 320
A9: 4. Anandan Ajikumar | B9: Sydney Cricket Ground | C9: Away( West Indies/ Scotland ): 5000 ( Won ) | D9: Against England(Test): 1 | E9: 4. The Ashes( Away ) | F9: 3. Sai Naveen - 5k | G9: Players Awards: 2300 | J9: Home(Pakistan): 5000 ( Won ) | K9: Trophy Cabinet (Test) | L9: Player | M9: Award | N9: Credits | O9: Player | P9: Award | Q9: Credits | S9: T20 Tournament | T9: 7 | U9: =T9*6000 -> 42000 | V9: =T9*60 -> 420
A10: 5. Anik Dey Shanto | B10: Optus Stadium | Free T20 WC | C10: Home ( Newzealand) : 5000 bet ( Lost ) | D10: Against Newzealand: 2 | E10: 5. Southee Cummins ( Away ) | F10: 4. Bhavesh B - 5k | G10: 1. Sai Naveen | J10: Away(Pakistan): 5000 (Won) | K10: Benaud-Qadir | L10: 1. Abrar Ali | M10: Best Batsman(1000): 1 | N10: 1000 | O10: 1. Arnab Sarkar | P10: Man of the match(5000): 1 | Q10: 822000 | S10: Total Credits | U10: =U8+U9 -> 58000 | V10: =V8+V9 -> 740
A11: 6. Ankan Biswas | B11: Adelaide Oval | C11: Home ( West Indies): 5000 bet ( Lost ) | E11: 6. Southern Challenge (Away) | F11: 5. Vaibhav Batra - 5k | G11: Man of the match: 1 | J11: Away(Scotland): 5000 (Won) | K11: Scottish Wall | L11: 2. Keshav Shah | M11: Man of the match(2000): 1 | N11: =3000+5400 -> 8400 | P11: Best Bowler(3000): 4 | R11: 2. Anurag Raj | S11: Club Series | T11: 7 | U11: =T11*1000 -> 7000 | V11: =T11*20 -> 140
A12: 7. Anurag Raj Gautam | B12: Sydney Show Ground | Franchise League L1 | Upgraded | C12: Away( Scotland): 5000 bet ( Lost ) | E12: 7. Kiwi Kangaroo (Away) | F12: 6. Saketh Balne - 5k | G12: • vs Scotland: 500 | J12: Home(Scotland): 5000 (Won) | K12: Aussie Wall | M12: Best Bowler(1000): 1 | P12: Most Dot Balls(1000): 5 | S12: T20 Tournament | T12: 4 | U12: =T12*6000 -> 24000 | V12: =T12*60 -> 240
A13: 8. Aqi Syed | B13: Marvel Cricket Stadium | C13: Home( Afghanistan): 7000 bet ( Won ) | D13: Whitewash lose: | E13: 8. Kingfisher Cup (Home) | F13: 7. Summan Baig to Pak - 2k | G13: Most Sixes: 1 | J13: Home (England): 5000 (Lost) | K13: Sydney Cup | M13: Team of the tournament - 5400 | P13: Best Bowler of the tournament: 800000 | S13: T20 Series | T13: 1.5 | U13: =T13*3000 -> 4500 | V13: =T13*60 -> 90
A14: 9. Ashwini Verma | B14: The Gabba | C14: Away( England ): 10000 ( Won ) | D14: -1000 | E14: 9. KFC T20 Cup (Home) | F14: 8. Srinidhi (10k) - SA Chairman | G14: • vs Scotland: 300 | J14: Away(England): 5000 (Lost) | K14: Poker Cup | L14: 3. Waqas Mughal | M14: Best Bowler(1000): 1 | N14: 1000 | O14: 2. Rahul Gadia | P14: Most Sixes(1000): 2 | Q14: 2000 | S14: ODI Tournament | T14: 1 | U14: =T14*10000 -> 10000 | V14: =T14*100 -> 100
A15: 10. Achu Achu | B15: Ninja Stadium Hobart | C15: Away ( England ): 5000 bet ( Lost ) | D15: Against Newzealand: 1 | E15: 10. IPL Challenger Trophy (Away) | F15: 9. Donald (10k) - SA Chairman | G15: 2. Bhavesh B | J15: Home(Bangladesh): 5000 (Won) | K15: Orange - Yellow Trophy | L15: 4. Arnab Sarkar | M15: Man of the match(2000): 1 | N15: =3000+25000+50000+5400 -> 83400 | O15: 3. Malik Zubair | P15: Man of the match(5000): 1 | Q15: 8000 | S15: T10 Series | T15: 1 | U15: =T15*2000 -> 2000 | V15: =T15*40 -> 40
A16: 11. Chintan Poojari | B16: Level 2 Stadiums | C16: Away ( UAE ): 5000 bet ( Lost ) | D16: Against Scotland: 1 | E16: 11. Great Southern Dutch (Home) | F16: 10. Noor from WI - 10000 | G16: Most Sixes: 1 | J16: Away(Bangladesh): 5000 (Won) | K16: Bee Trophy | M16: Best Bowler(1000): 2 | P16: Best Bowler(3000): 1 | S16: Franchise League
A17: 12. Chiranjibi Samal | B17: None | C17: Away ( Newzealand ): 5000 bet ( Won ) | E17: 12. The Dublin Showdown (Away) | F17: 11. Mahi to SA - 2500 | G17: • vs Afghanistan: 300 | J17: Home(Netherlands): 5000 (Lost) | K17: Southern Cross Test | M17: Golden Ball Award(25000) | O17: 4. Muhammad Noor | P17: Best Batsman(3000): 1 | Q17: 5000 | S17: 100 | T17: 1 | U17: =T17*1500 -> 1500 | V17: =T17*60 -> 60
A18: 13. Hur Ali | B18: Level 1 Stadiums | C18: Away (Pakistan): 10000 bet (Won) | E18: 13. Last Of the Summer (Home) | F18: 12. K Rakesh to SA - 2500 | G18: 3. Anurag | J18: Away(Netherlands): 5000 (Won) | K18: The Gulf Test Series | M18: Player of the Tournament(50000) | P18: Most Sixes(1000): 2 | S18: BBL | T18: 4 | U18: =T18*1500 -> 6000 | V18: =T18*60 -> 240
A19: 14. Kuldeep Roy | B19: None | C19: Away (Newzealand): 5000 bet (Won) | F19: 13. Harsh from Qatar - 60000 | G19: Most Sixes: 1 | J19: Home(Srilanka): 5000 (Won) | K19: Kiwi Kangaroo Trophy | M19: Team of the tournament - 5400 | O19: 5. Abrar Ali | P19: Best Batsman(3000): 1 | Q19: 3000 | S19: Total Credits | U19: =U11+U12+U17+U18+U13+U14+U15 -> 55000 | V19: =V11+V12+V17+V18+V13+V14+V15 -> 910
A20: 15. Malaram Patel | C20: Home(Srilanka): 5000 bet (Won) | F20: 14. Ashfak from BD - 23000 | G20: • vs Afghanistan: 300 | J20: Home(Newzealand): 5000 (Won) | L20: 5. Harsh Dubey | M20: Best Batsman(1000): 1 | N20: =1000+25000+5400 -> 31400 | O20: 6. Chiranjibi Samal | P20: Best Batsman(3000): 1 | Q20: 4000 | R20: 3. Arnab Sarkar | S20: Club Series | T20: 5 | U20: =T20*1000 -> 5000 | V20: =T20*20 -> 100
A21: 16. Malik Zubair | C21: Home (England): 10000 bet (Won) | F21: 15. Mohsin to USA - free | G21: Economical bowler: 1 | J21: Away(UAE): 10000 (Won) | M21: Golden Bat Award(25000) | P21: Most Sixes(1000): 1 | S21: T20 Tournament | T21: 4 | U21: =T21*6000 -> 24000 | V21: =T21*60 -> 240
A22: 17. Manish Indoria | C22: Home(India): 5000 bet (Lost) | F22: 16. Arjun to Ireland - 7000 | G22: • vs West Indies: 300 | J22: Away(Srilanka): 10000 (Lost) | M22: Team of the tournament - 5400 | O22: Group Stage Exit | Q22: 200000 | S22: T10 Series | T22: 2 | U22: =T22*2000 -> 4000 | V22: =T22*40 -> 80
A23: 18. Muhammad Noor | C23: Away(India): 5000 bet (Won) | F23: 17. Adil to USA: 7000 | G23: 4. Rizwan | J23: Away(Newzealand): 10000(Won) | L23: 6. Mohammaed Noor | M23: Man of the match(2000): 1 | N23: 3000 | O23: Fantasy League: 3rd Place | Q23: 100000 | S23: Club Series | T23: 1 | U23: =T23*1000 -> 1000 | V23: =T23*20 -> 20
A24: 19. Nidasha Romanoff | C24: Home(Netherlands): 10000 bet (Won) | F24: 18. Lal to Italy: 50000 | G24: Economical bowler: 1 | J24: Home(India): 10000(Lost) | M24: Best Bowler(1000): 1 | S24: ODI Series | T24: 1 | U24: =T24*5000 -> 5000 | V24: =T24*100 -> 100
A25: 20. Rahul Gadia | C25: Home(England): 10000 bet (Lost) | F25: 19. Kashif to Zim: 5000 | G25: • vs Afghanistan: 300 | I25: Players Awards & Credits | L25: 7. Waqas Mughal | M25: Man of the match(2000): 1 | N25: 2000 | S25: ODI Tournament | T25: 1.5 | U25: =T25*10000 -> 15000 | V25: =T25*100 -> 150
A26: 21. Rizwan Mansoori | C26: Home(UAE): 3000 bet (Lost) | F26: 20. Waqas to BD: 200000 | G26: 5. Abrar | I26: Player | J26: Award | K26: Credits | L26: 8. Rahul Gadia | M26: Best Batsman(1000): 1 | N26: 1000 | S26: Franchise League
A27: 22. Zeeshan Yaqoob Gujjar | C27: Away(West Indies): 10000 bet (Lost) | F27: 21. Ashfaq (Banned) | G27: Most Sixes: 1 | I27: 1. Rizwan Mansoori | J27: Man of the Match: 2 (1000) | K27: 4000 | L27: Champions | N27: 300000 | S27: BBL | T27: 8 | U27: =T27*1500 -> 12000 | V27: =T27*60 -> 480
C28: Away(USA): 10000 bet (Lost) | F28: 22. Rima from Pak: 25000 | G28: • vs West Indies: 300 | J28: Best Batsman: 3 (500) | S28: BPL | T28: 2 | U28: =T28*1500 -> 3000 | V28: =T28*60 -> 120
C29: Home(Srilanka & UAE): 15000 (Lost) | F29: 23. Adil from Zim: 60000 | G29: Eliminated in Group Stage: 10k | J29: Best Bowler: 1 (500) | S29: IPL | T29: 2.5 | U29: =T29*1500 -> 3750 | V29: =T29*60 -> 150
C30: Away(Zimbabwe): 5000 (Lost) | F30: 24. Rima to Pak: 25000 | I30: 2. Keshav Shah | J30: Man of the Match: 2 (1000) | K30: 4000 | S30: KCL ( Commentory ) | T30: 1 | U30: =T30*1500 -> 1500 | V30: =T30*60 -> 60
C31: Away(Ireland): 6000 (Won) | F31: 25. Harsh to USA: 100000 | G31: Players Awards: 15000 | J31: Best Batsman: 2 (500) | S31: IPL | T31: 1 | U31: =T31*1500 -> 1500 | V31: =T31*60 -> 60
C32: Away(Canada): 5000 (Lost) | F32: 26. Shahzad to Spain: 5000 | G32: 1. Anurag Raj | J32: Best Bowler: 2 (500) | S32: CPL ( Commentory ) | T32: 1 | U32: =T32*1500 -> 1500 | V32: =T32*60 -> 60
C33: Home(West Indies): 5000 (Lost) | F33: 27. Kuldeep from Arg: 10000 | G33: Most Maidens(2): 5000 | I33: 3. Saubhagya Gupta | J33: Man of the Match: 1 (1000) | K33: 1500 | S33: Total Credits | U33: =U20+U21+U22+U27+U28+U29+U30+U31+U23+U32+U24+U25 -> 77250 | V33: =V20+V21+V22+V27+V28+V29+V30+V31+V23+V32+V24+V25 -> 1620
C34: Away(West Indies): 5000 bet (Lost) | F34: 28. Chintan from Zim: 20000 | G34: 2. Sai Naveen | J34: Best Batsman: 0 (500) | R34: 4. Abrar Ali | S34: Club Series | T34: 1 | U34: =T34*1000 -> 1000 | V34: =T34*20 -> 20
C35: Home(India): 5000 bet (Won) | G35: Highest Individual Score(140): 5000 | J35: Best Bowler: 1 (500) | S35: T20 Tournament | T35: 0.5 | U35: =T35*6000 -> 3000 | V35: =T35*60 -> 30
C36: Home(West Indies): 10000 (Lost) | G36: 3. Yasin Iqbal | I36: 4. Arnab Sarkar | J36: Man of the Match: 5 (1000) | K36: 7500 | S36: Total Credits | U36: =U34+U35 -> 4000 | V36: =V34+V35 -> 50
C37: Home(Canada & West Indies): 10000 (Lost) | G37: World cup operations Excellence: 5000 | J37: Best Batsman: 1 (500) | R37: 5. Keshav Shah | S37: Club Series | T37: 8 | U37: =T37*1000 -> 8000 | V37: =T37*20 -> 160
C38: Away(Newzealand): 10000 (Lost) | J38: Best Bowler: 4 (500) | S38: T20 Tournament | T38: 2.5 | U38: =T38*6000 -> 15000 | V38: =T38*60 -> 150
G39: Hosting Nation: 30000 | I39: 5. Anand Kumar | J39: Man of the Match: 0 (1000) | K39: 500 | S39: T10 Series | T39: 2 | U39: =T39*2000 -> 4000 | V39: =T39*40 -> 80
J40: Best Batsman: 1 (500) | S40: T20 Series | T40: 9 | U40: =T40*3000 -> 27000 | V40: =T40*60 -> 540
...

Sheet Bangladesh
A1: Board: Bangladesh
A2: Chairman: Sai Naveen | CEO: Bhargab Kashyap
A3: TITLE SPONSORS: CrazieCric asmr
A4: Credits left:
A5: =100000+B7+C7+D7+F7+I7+A84+E19+D28+J7+S7+P7+M7+I18+E24 -> 5510745
A6: Players | B6: Stadium: | C6: Traded Palyers: | D6: International Series: | E6: Trophy Cabinet ( International Series) | F6: IOCF WORLD TEST CHAMPIONSHIP 🏆: | I6: Player limit exceeded: -10000 | J6: CONTINENTAL CUP 2026 🏆: ( ASIA ) | M6: Women's Global League 2026 🏆: | P6: ODI WORLD CUP 2026 🏆: | S6: Umpires Credits :
A7: 1. Abhishek Adhikary | B7: -230000 | C7: =10000-400000-15000 -> -405000 | D7: 46000 | E7: 1. Greater Asia Cup ( Home ) | F7: =F9+G9+H9 -> -21000 | I7: -20000 | J7: =-60000+J10 -> 123200 | M7: =M9 -> 330000 | P7: =P9 -> 1795000 | S7: =V10+V21+V35+V40+V44+V54+V57+V62+V65 -> 381250
A8: 2. Ahsan Siddiqui | B8: Level 3 Stadiums | C8: 1. Yasin Iqbal - 5k | D8: Home ( Afghanistan ): 5000 bet ( Won ) | E8: 2. Boult Taskin ( Away ) | F8: Player Awards | G8: Match Bet Credits | H8: Entry Credits | I8: 1. 20 to 25: 10000 | J8: Hosting Amount: 60k | M8: Players & Match Awards | P8: Players & Match Awards | S8: Umpire | T8: Details | U8: Total Matches | V8: Credits | W8: Points
A9: 3. Ali Khan | B9: Padma - Meghna Cricket Arena | C9: 2. Karan Kumar - 5k | D9: Away ( Newzealand ): 5000 bet ( Won ) | E9: 3. Battle of Giants ( Away ) | F9: =H27+H30+H33+H36+H39+H42+H45+H48 -> 13000 | G9: -29000 | H9: -5000 | I9: 2. 25 to 30: 10000 | J9: Players & Match Awards | M9: =O11+O12+O13+O14+O15 -> 330000 | P9: =R11+R13+R16+R18+R19+R20+R24+R26+R27+R28+R29 -> 1795000 | S9: 1. Vaibhav Batra | T9: Club Series | U9: 0.5 | V9: =U9*1000 -> 500 | W9: =U9*20 -> 10
A10: 4. Allabux Kapri | B10: Hilsha Heritage Stadium | Franchise League L1 | Upgraded | C10: 3. Sai Naveen - 5k | D10: Home (West Indies): 7000 bet (Lost) | E10: 4. Dutch Bangla Battle (Away) | G10: Away ( West Indies ): 6000 bet ( Lost ) | H10: Trophy Cabinet (Test) | J10: =L12+L15+L18+L21+L22 -> 183200 | M10: Player | N10: Award | O10: Credits | P10: Player | Q10: Award | R10: Credits | T10: Total Credits | V10: =V9 -> 500 | W10: =W9 -> 10
A11: 5. Asad KB | B11: Karnaphuli Cricket Park | C11: 4. Bhavesh B - 5k | D11: Away (England): 10000 bet ( Won ) | E11: 5. Lords Clash (Away) | G11: Home ( West Indies ): 6000 bet ( Lost ) | H11: 1. Redball War ( Away ) | J11: Player | K11: Award | L11: Credits | M11: Best Women Talent Discovery Board | O11: 20000 | P11: 1. Ali Khan | Q11: Man of the match(5000): 1 | R11: 7000 | S11: 2. Sai Naveen | T11: Club Series | U11: 1.5 | V11: =U11*1000 -> 1500 | W11: =U11*20 -> 30
A12: 6. Ishaq Farid | B12: Mango Fortress Stadium | C12: 5. Vaibhav Batra - 5k | D12: Away (Netherlands): 4000 bet (Won) | E12: 6. The Royal Protea Trophy (Home) | G12: Away (England): 10000 bet (Won) | H12: 2. North Sea-Bay Challenge | J12: 1. Bhargab Kashyap | K12: Man of the match(2000): 2 | L12: =7000+5400 -> 12400 | M12: Isitha | N12: Best Captain | O12: 30000 | Q12: Most Sixes(1000): 2 | T12: T10 Series | U12: 1.5 | V12: =U12*2000 -> 3000 | W12: =U12*40 -> 60
A13: 7. Ishita Sharma | B13: Sylhet Jewel Stadium | C13: 6. Saketh Balne - 5k | D13: Home (Pakistan): 5000 bet (Lost) | E13: 7. Anglo Bengal ODI Trophy (Away) | G13: Home (Scotland): 5000 bet (Won) | H13: 3. Tiger Tulip (Home) | K13: Best Batsman(1000): 3 | M13: Tasnim | N13: Best Bowler | O13: 30000 | P13: 2. Sai Naveen | Q13: Best Bowler(3000): 1 | R13: 5000 | T13: Test Tournament | U13: 5.5 | V13: =U13*8000 -> 44000 | W13: =U13*80 -> 440
A14: 8. Karan Kumar | B14: Sundarbans Cricket Fortress | C14: Harsh Dubey(Ban) - 20000 | D14: Away(England): 5000 bet (Won) | E14: 8. Tiger Orange Cup (Home) | G14: Away (Scotland): 5000 bet (Lost) | H14: 4. Solidarity Cup (Away) | K14: Team of the tournament - 5400 | N14: Player of the tournament | O14: 50000 | Q14: Most Sixes(1000): 1 | T14: ODI Series | U14: 1 | V14: =U14*5000 -> 5000 | W14: =U14*100 -> 100
A15: 9. Kalpana Bhujel | B15: Sonar Bangla Cricket Arena | C15: 8. Aashutosh from ND: 15000 | D15: Away(Pakistan): 5000 bet (Lost) | E15: 9. American-Bangla Trophy (Away) | G15: Home (Pakistan): 5000 bet (Lost) | H15: 5. Arabia-Bengal Test (Away) | J15: 2. Ahsan Siddiqui | K15: Man of the match(2000): 2 | L15: =5000+5400 -> 10400 | M15: Champions | O15: 200000 | Q15: Most Dot Balls(1000): 1 | T15: ODI Tournament | U15: 3 | V15: =U15*10000 -> 30000 | W15: =U15*100 -> 300
A16: 10. Kaushik Kalita | B16: Sands cox's Bazar | C16: 9. Bhavin to SA - 2500 | D16: Home(South Africa): 5000 bet (Won) | E16: 10. Tigers - Lions Forest Trophy (Home) | G16: Home(Netherlands): 4000 bet (Won) | K16: Best Bowler(1000): 1 | P16: 3. Yasin Iqbal | Q16: Man of the match(5000): 1 | R16: 7000 | T16: Club Tournament | U16: 1 | V16: =U16*2000 -> 2000 | W16: =U16*20 -> 20
A17: 11. Mahira | B17: Level 2 Stadiums | C17: 10. Raksh to SA - 2500 | D17: Away(England): 5000 bet (Lost) | G17: Away(Newzeland): 6000 bet (Lost) | I17: Sponsors | K17: Team of the tournament - 5400 | Q17: Most Dot Balls(1000): 2 | T17: Franchise League
A18: 12. Manan Irfan | B18: None | C18: 11. Saketh to SA - 2500 | D18: Home(Netherlands/West Indies): 15000 (Lost) | E18: Whitewash lose: | G18: Home(Newzealand): 5000 bet (Lost) | I18: 100000 | J18: 3. Yasin Iqbal | K18: Man of the match(2000): 1 | L18: =4000+5400 -> 9400 | P18: 4. Manan Irfan | Q18: Most Sixes(1000): 1 | R18: 1000 | T18: KCL | U18: 1 | V18: =U18*1500 -> 1500 | W18: =U18*60 -> 60
A19: 13. Partha Pratim Bora | B19: Level 1 Stadiums | C19: 12. Bhavesh to SA - 2500 | D19: Away(England): 5000 bet (Lost) | E19: -1000 | G19: Away(Pakistan): 5000 bet (Won) | I19: 1. Crazie Cric asmr (Title Sponsors) | K19: Best Bowler(1000): 2 | P19: 5. Princhi Bora | Q19: Most Dot Balls(1000): 1 | R19: 1000 | T19: BPL | U19: 2 | V19: =U19*1500 -> 3000 | W19: =U19*60 -> 120
A20: 14. Pinky Kashyap | B20: None | C20: 13. Ahmed to Qatar - 2000 | D20: Away(England): 5000 bet (Won) | E20: 1. Sons & Daughter (Pakistan) : Home | G20: Away(Australia): 5000 bet (Lost) | K20: Team of the tournament - 5400 | P20: 6. Waqas Mughal | Q20: Man of the match(5000): 2 | R20: 20000 | T20: IPL | U20: 1 | V20: =U20*1500 -> 1500 | W20: =U20*60 -> 60
A21: 15. Popi Sultana | C21: 14. Ebad to Qatar - 2000 | D21: Home(UAE): 5000 bet (Lost) | E21: 2. The Stars & Tigers series (USA) : Home | G21: Home(Australia): 5000 bet (Lost) | J21: 4. Sai Naveen | K21: Best Bowler(1000): 1 | L21: 1000 | Q21: Best Batsman(3000): 1 | T21: Total Credits | V21: =V11+V12+V13+V18+V19+V20+V14+V15+V16 -> 91500 | W21: =W11+W12+W13+W18+W19+W20+W14+W15+W16 -> 1190
A22: 16. Princhi Pratim Bora | C22: 15. Abdul to Qatar - 2000 | D22: Home (Netherlands): 7000 bet (Won) | G22: Home( Bangladesh): 5000 bet (Lost) | J22: Runners-UP | L22: 150000 | Q22: Best Bowler(3000): 2 | S22: 3. Yasin Iqbal | T22: Club Series | U22: 1 | V22: =U22*1000 -> 1000 | W22: =U22*20 -> 20
A23: 17. Rahees Ashiq | C23: 16. Ashutosh to NZ- 5000 | D23: Away(Italy): 5000 (Lost) | E23: Whitewash Won: | G23: Away(Qatar): 5000 bet (Won) | Q23: Most Sixes(1000): 1 | T23: Club Tournament | U23: 1 | V23: =U23*2000 -> 2000 | W23: =U23*20 -> 20
A24: 18. Rajab Baloch | C24: 17. Rao Abul to Qatar - 15000 | D24: Home(USA): 5000 (Lost) | E24: 1000 | G24: Home(South Africa): 10000 (Lost) | P24: 7. Tanusri Dutta | Q24: Best Batsman(3000): 1 | R24: 4000 | T24: T10 Series | U24: 1 | V24: =U24*2000 -> 2000 | W24: =U24*40 -> 40
A25: 19. Shubham Dudi | C25: 18. Harsh Dubey to Qatar - 15000 | D25: Away(USA): 5000 (Won) | E25: 1. Tigers - Lions Forest Trophy (Home) | F25: Players Awards & Credits | Q25: Most Sixes(1000): 1 | T25: T20 Series | U25: 2 | V25: =U25*3000 -> 6000 | W25: =U25*60 -> 120
A26: 20. Sidd V Jain | C26: 19. Adithya to RSA - 15000 | D26: Home(England): 10000 (Won) | F26: Player | G26: Award | H26: Credits | P26: 8. Ahsan Siddiqui | Q26: Emerging Player of the Tournament: 200000 | R26: 200000 | T26: ODI Series | U26: 3 | V26: =U26*5000 -> 15000 | W26: =U26*100 -> 300
A27: 21. Suraj Shetty | C27: 20. Ritik from Ned - 1000 | D27: IOCF HALL OF FAME | F27: 1. Yasin Iqbal | G27: Man of the Match: 3 (1000) | H27: 6000 | P27: Semifinalists | R27: 1000000 | T27: Test Tournament | U27: 1.5 | V27: =U27*8000 -> 12000 | W27: =U27*80 -> 120
A28: 22. Tasnim | C28: 21. Ashfak to Aus - 23000 | D28: 50000 | G28: Best Batsman: 1 (500) | P28: Prediction Contest: 1st Place | R28: 500000 | T28: ODI Tournament | U28: 4.5 | V28: =U28*10000 -> 45000 | W28: =U28*100 -> 450
A29: 23. Tansuri Dutta | C29: 22. Rohan (10k) - USA Chairman | D29: Yasin Iqbal | G29: Best Bowler: 5 (500) | P29: Fantasy League: 5th Place | R29: 50000 | T29: Franchise League
A30: 24. Tanushree | C30: 23. Gaurav to USA - 2000 | D30: Ice in their Veins : Top Wicket Taker | F30: 2. Karan Kumar | G30: Man of the Match: 0 (1000) | H30: 1000 | T30: 100 | U30: 1.5 | V30: =U30*1500 -> 2250 | W30: =U30*60 -> 90
A31: 25. Vaibhav Batra | C31: 24. Adil from USA: 10000 | G31: Best Batsman: 2 (500) | T31: PSL | U31: 2 | V31: =U31*1500 -> 3000 | W31: =U31*60 -> 120
A32: 26. Waqas Mughal | C32: 25. Waqas from Aus: 200000 | G32: Best Bowler: 0 (500) | T32: KCL | U32: 2 | V32: =U32*1500 -> 3000 | W32: =U32*60 -> 120
A33: 27. Yasin Iqbal | C33: 26. Sajjad to Canada: 25000 | F33: 3. Harsh Dubey | G33: Man of the Match: 0 (1000) | H33: 1000 | T33: BPL | U33: 1 | V33: =U33*1500 -> 1500 | W33: =U33*60 -> 60
C34: 27. Allabux from Canada: 25000 | G34: Best Batsman: 2 (500) | T34: IPL | U34: 1 | V34: =U34*1500 -> 1500 | W34: =U34*60 -> 60
C35: 25. Adil to USA: Free | G35: Best Bowler: 0 (500) | T35: Total Credits | V35: =V22+V23+V24+V25+V26+V27+V30+V31+V32+V33+V34+V28 -> 94250 | W35: =W22+W23+W24+W25+W26+W27+W30+W31+W32+W33+W34+W28 -> 1520
C36: 26. Shubham from Kenya: 15000 | F36: 4. Ahsan Siddiqui | G36: Man of the Match: 1 (1000) | H36: 1500 | S36: 4. Harsh Dubey | T36: T20 Series | U36: 1 | V36: =U36*3000 -> 3000 | W36: =U36*60 -> 60
C37: 27. Sid from SA: 100000 | G37: Best Batsman: 0 (500) | T37: Franchise League
C38: 28. Kaushik from SA: 100000 | G38: Best Bowler: 1 (500) | T38: PSL | U38: 0.5 | V38: =U38*1500 -> 750 | W38: =U38*60 -> 30
C39: 29. Gamshad to Spain: Free | F39: 5. Manan Irfan | G39: Man of the Match: 0 (1000) | H39: 500 | T39: BBL | U39: 0.5 | V39: =U39*1500 -> 750 | W39: =U39*60 -> 30
G40: Best Batsman: 1 (500) | T40: Total Credits | V40: =V36+V38+V39 -> 4500 | W40: =W36+W38+W39 -> 120
...

Sheet Canada
A1: Board: Canada
A2: Chairman: Farhan Rizvi | CEO: Faraz Kapri
A3: Credits left:
A4: =100000+B6+C6+E6+J6+A27 -> 251500
A5: Players | B5: Stadium: | C5: International Series: | D5: Trophy Cabinet ( International series) | E5: Umpires Credits : | J5: Associate Nations CUP 2026 🏆:
A6: 1. Aftab | B6: -30000 | C6: 14500 | D6: 1. Croco-Owl Series ( Away ) | E6: =H9+H11 -> 4000 | J6: =J8 -> 142000
A7: 2. Akash | B7: Level 3 Stadiums | C7: Away( Zimbabwe ): 5000 bet ( Won ) | D7: 2. Red Leaf Cup (Home) | E7: Umpire | F7: Details | G7: Total Matches | H7: Credits | I7: Points | J7: Players & Match Awards
A8: 3. Arsalan Kapri | B8: CAA Centre | C8: Home(USA & Uganda): 5000 bet (Won) | D8: 3. ODI WC Warmup 1 (Home) | E8: 1. Farhan Rizvi | F8: Club Series | G8: 3 | H8: =G8*1000 -> 3000 | I8: =G8*20 -> 60 | J8: =L10+L15+L17+L18 -> 142000
A9: 4. Ayaz | B9: Level 2 Stadiums | C9: Away(USA): 3000 (Lost) | D9: 4. Rhino - Owl Cup (Away) | F9: Total Credits | H9: =H8 -> 3000 | I9: =I8 -> 60 | J9: Player | K9: Award | L9: Credits
A10: 5. Blassy | B10: None | C10: Home(West Indies): 5000 (Lost) | D10: 5. Irish Canadian Cup (Away) | E10: 2. Faraz Kapri | F10: Club Series | G10: 1 | H10: =G10*1000 -> 1000 | I10: =G10*20 -> 20 | J10: 1. Naveen Gupta | K10: Man of the Match(2000): 3 | L10: 50000
A11: 6. Chaitanya Deshpande | B11: Level 1 Stadiums | C11: Home(Australia): 5000 (Won) | D11: 6. The Latitude Clash (Away) | F11: Total Credits | H11: =H10 -> 1000 | I11: =I10 -> 20 | K11: Best Batsman (1000): 1
A12: 7. Faizan | B12: None | C12: Away(South Africa): 5000 (Won) | D12: 7. RED & GREEN RIVALRY II (Away) | K12: Best Bowler(1000): 3
A13: 8. Manjeet | C13: Away(Ireland): 5000 (Won) | K13: Best Bat Average(10000)
A14: 9. Mansoor | C14: Home(Newzealand): 5000 (Lost) | K14: Player of the Tournament(30000)
A15: 10. Najibullah | C15: Away(PNG,Netherlands & West Indies): 7500 (Lost) | J15: 2. Rehan | K15: Best Batsman (1000): 1 | L15: 16000
A16: 11. Ahsas Kapri | C16: Home(Spain & Kenya): 5000 bet (Lost) | K16: Best Batsman of the Tournament(15000)
A17: 12. Neak Mohammad | C17: Away(Australia & West Indies): 10000 (Lost) | J17: 3. Akash Pol | K17: Best Bowler(1000): 1 | L17: 1000
A18: 13. Rehan | C18: Away(West Indies): 5000 (Won) | J18: Runners Up | L18: 75000
A19: 14. Romeo | B19: Traded Palyers: | C19: Away(Ireland): 5000 (Lost)
A20: 15. Sajjad Kapri | B20: 0 | C20: Away(Ireland): 5000 (Won)
A21: 16. Sahnavaz | B21: 1. Sajjad from Bangladesh: 25000
A22: 17. Shebin | B22: 2. Allabux to Bangladesh: 25000
A23: 18. Vishesh | B23: 3. Naveen to PNG: Free
A24: 19. Fawad Kapri
A26: All Franchise League Credits Updates :
A27: =A29 -> 21000
A28: Qatar Elite Crown League :
A29: =A32 -> 21000
A30: 2026
A31: All Team Profit:
A32: =A35+B35+C35+D35+E35+F35+G35+H35 -> 21000
A33: AL KHOR PREDATORS | B33: AL RAYYAN RAIDERS | C33: AL WAKRAH DUKES | D33: DOHA STALLIONS | E33: LUSAIL KNIGHTS | F33: MESAEID BLAZE | G33: QATAR VENOMS | H33: UMM SALAL SPARTANS
A34: Team Profit: | B34: Team Profit: | C34: Team Profit: | D34: Team Profit: | E34: Team Profit: | F34: Team Profit: | G34: Team Profit: | H34: Team Profit:
A35: 0 | B35: 15000 | C35: 0 | D35: 6000 | E35: 0 | F35: 0 | G35: 0 | H35: 0
B36: 1. Naveen Gupta | D36: 1. Blessy
B37: Salary: 15000 | D37: Salary: 6000

Sheet England
A1: Board: England
A2: Chairman: Diljith Das | CEO: Sujith CS Ctr
A3: TITLE SPONSORS: Cricket Circle
A4: KIT SPONSORS: S-Mark SportsWear
A5: MERCHANDISE SPONSORS: Brand Sports
A6: Credits left:
A7: =100000+B9+C9+D9+F9+G9+I9+A74+E30+L9+F28+E34+N9+W9+F34+T9+Q9 -> 3834985
A8: Players | B8: Stadium: | C8: International Series: | D8: Whitewash lose: | E8: Trophy Cabinet ( International series) | F8: Traded Player: | G8: IOCF T20 WORLD CUP 🏆 : | I8: IOCF WORLD TEST CHAMPIONSHIP 🏆: | L8: EMERGING TALENTS LEAGUE: | N8: CONTINENTAL CUP 2026 🏆: ( EURO ) | Q8: Women's Global League 2026 🏆: | T8: ODI WORLD CUP 2026 🏆: | W8: Umpires Credits :
A9: 1. Aash Muhammad | B9: -260000 | C9: 87000 | D9: -1500 | E9: 1. Sir Vivian Richards Trophy ( Away ) | F9: 24000 | G9: 92600 | I9: =I11+J11+K11 -> -1000 | L9: 135000 | N9: =N11 -> 403200 | Q9: =Q11 -> 50000 | T9: =T11 -> 1053000 | W9: =Z18+Z23+Z40+Z43+Z51+Z54+Z57+Z59+Z61 -> 481000
A10: 2. Abhijith | B10: Level 3 Stadiums | C10: Away( West Indies ): 10000 bet ( Won ) | D10: 1. Anderson Tendulkar ( India ) | E10: 2. Anglo Scotish Trophy ( Home ) | F10: 1. Subaida to SA : 7000 | G10: Entry: -5000 | H10: Players Awards: 30000 | I10: Player Awards | J10: Match Bet Credits | K10: Entry Credits | L10: Tournament Awards: | M10: Award Winners | N10: Players & Match Awards | Q10: Players & Match Awards | T10: Players & Match Awards | W10: Umpire | X10: Details | Y10: Total Matches | Z10: Credits | AA10: Points
A11: 3. Achuz Sukumaran | B11: Lords International Stadium | C11: Home( India ): 5000 bet ( Lost ) | D11: 2. The Ashes ( Test - Australia ) | E11: 3. Commonwealth Crown ( Home ) | F11: 2. Hirak to Ned: 5000 | G11: Players Awards: 7600 | H11: 1. Toby Joseph | I11: =K29+K32+K35+K38+K41+K44+K47+K50+K53+K56+K59 -> 15000 | J11: -11000 | K11: -5000 | L11: Match of the Tournament: | M11: Eng vs WI (15000) | N11: =P13+P17+P18+P21+P23+P25 -> 403200 | Q11: =S13+S14 -> 50000 | T11: =V13+V14+V19+V21+V23+V24+V26+V27+V28 -> 1053000 | W11: 1. Diljith Das | X11: Club Series | Y11: 11 | Z11: =Y11*1000 -> 11000 | AA11: =Y11*20 -> 220
A12: 4. Ajin P Anil | B12: WGG International Stadium | C12: Home ( Scotland ): 5000 bet ( Won ) | E12: 4. Crown series ( Home ) | F12: 3. Ashuotsh to Ned: 5000 | G12: 1. Rahees | H12: Most Dot Balls(65): 5000 | J12: Home(West Indies): 6000 bet (Lost) | K12: Trophy Cabinet (Test) | L12: Best Talent Discovery Board: | M12: England (10000) | N12: Player | O12: Award | P12: Credits | Q12: Player | R12: Award | S12: Credits | T12: Player | U12: Award | V12: Credits | X12: T20 Series | Y12: 0.5 | Z12: =Y12*3000 -> 1500 | AA12: =Y12*40 -> 20
A13: 5. Arjun AKJ | B13: The Rose Bowl | C13: Away ( Afghanistan): 3000 bet ( Lost ) | E13: 5. Yuvraj Flintoff ( Away ) | F13: 4. Subaida to Italy: 7000 | G13: Man of the match: 1 | H13: 2. Rejith Mohan | J13: Home (Italy): 5000 bet (Won) | K13: 1. Royal Test | L13: Fair Play: | M13: England(15000) | N13: 1. Safeer Babu | O13: Man of the match(2000): 4 | P13: =12000+25000+5400 -> 42400 | Q13: Best Women Talent Discovery Board | S13: 20000 | T13: 1. Sujith CS Ctr | U13: Best Bowler(3000): 1 | V13: 3000 | X13: Test Tournament | Y13: 1.5 | Z13: =Y13*8000 -> 12000 | AA13: =Y13*80 -> 120
A14: 6. Dileep Kumar | B14: Trent Bridge | Franchise League L1 | Upgraded | C14: Home ( Srilanka): 5000 bet ( Lost) | E14: 6. Ashes Blitz ( Home ) | F14: 5. Vishnu to Italy: 3000 | G14: • vs Australia: 500 | H14: Fastest Century(24B): 5000 | J14: Home(Bangladesh): 10000 bet (Lost) | K14: 2. Royal Lion | L14: Best Batsman: | M14: Shajahan (20000) | O14: Best Bowler(1000): 4 | Q14: Sneha Jyothish | R14: Best Batsman | S14: 30000 | T14: 2. Safeer Babu | U14: Man of the match(5000): 2 | V14: 23000 | X14: Club Tournament | Y14: 1.5 | Z14: =Y14*2000 -> 3000 | AA14: =Y14*20 -> 30
A15: 7. Gowri Madhu | B15: The Oval | C15: Home ( Newzealand): 5000 bet ( Won ) | E15: 7. Dutch Anglo ( Away ) | F15: 6. Aneesh to WI: 20000 | G15: Economical bowler: 3 | H15: Most Fours:5000 | J15: Home (Pakistan): 10000 bet (Won) | K15: 3. Great Subcontinent Clash | L15: Player of the Tournament: | M15: Shajahan (25000) | O15: Golden Ball Award(25000) | U15: Best Batsman(3000): 1 | X15: Franchise League
A16: 8. Jyothish | B16: Old Trafford | C16: Home ( Pakistan): 5000 bet ( Won ) | E16: 8. Karachi London (Away ) | F16: 7. Harshad Vanimal | Removed | G16: • vs Australia: 300 | H16: Best Batsman: 10000 | J16: Home (India): 5000 bet (Won) | K16: 4. Fortress Cup | L16: Runners UP: | M16: 50000 | O16: Team of the tournament - 5400 | U16: Best Bowler(3000): 2 | X16: 100 | Y16: 3.5 | Z16: =Y16*1500 -> 5250 | AA16: =Y16*60 -> 210
A17: 9. Molly Stephan | B17: Yorkshire Headingley | C17: Home ( Australia ): 10000 bet ( Lost ) | E17: 9. London Trophy (Home) | F17: 8. Karthik Verma | Removed | G17: • vs West Indies: 300 | H17: 3. Diljith Das | J17: Away (Newzealand): 5000 bet (Lost) | K17: 5. London Trophy | N17: 2. Sanoop | O17: Best Batsman(1000): 1 | P17: =1000 -> 1000 | U17: Most Sixes(1000): 2 | X17: 100 ( Commentory ) | Y17: 1 | Z17: =Y17*1500 -> 1500 | AA17: =Y17*60 -> 60
A18: 10. Nechuz | B18: Somerset County Ground | C18: Away ( India ): 10000 bet ( Won ) | E18: 10. Northwave Trophy (Away) | F18: 9. Amith | Removed | G18: • vs Newzealand: 300 | H18: Fastest Fifty(10B): 5000 | J18: Away (Australia): 5000 bet (Won) | K18: 6. Imperial Lords | N18: 3. Rahees | O18: Man of the match(2000): 1 | P18: =3000+5400 -> 8400 | U18: Most Dot Balls(1000): 2 | X18: Total Credits | Z18: =Z11+Z12+Z16+Z17+Z13+Z14 -> 34250 | AA18: =AA11+AA12+AA16+AA17+AA13+AA14 -> 660
A19: 11. Nisham | B19: Level 2 Stadiums | C19: Home ( Australia ): 5000 bet ( Won ) | E19: 11. The Arabian Challenge (Home) | F19: 10. Sadik | Removed | G19: Most Sixes: 1 | J19: Home (Australia): 5000 bet (Won) | K19: 7. Royal WTC Clash | O19: Best Bowler(1000): 1 | T19: 3. Sunaif | U19: Best Batsman(3000): 1 | V19: 4000 | W19: 2. Achuz | X19: Club Series | Y19: 2 | Z19: =Y19*1000 -> 2000 | AA19: =Y19*20 -> 40
A20: 12. Rahees | B20: Middlesex Lords County Cricket Ground | C20: Away (England): 5000 bet (Won) | E20: 12. Anz ODI Clash (Home) | F20: 11. Shajahan | | Removed | G20: • vs Afghanistan: 300 | H20: Runners Up: 40000 | J20: Away(Qatar): 5000 bet (Lost) | O20: Team of the tournament - 5400 | U20: Most Sixes(1000): 1 | X20: Franchise League
A21: 13. Rashid | B21: Durahm Riverside Ground | C21: Home ( West Indies): 6000 bet (Lost) | E21: 13. Royal Anglo Trophy (Home) | F21: 12. Sujith to Portugal: 2000 | G21: 2. Aneesh | J21: Home(Netherlands): 5000 bet (Won) | N21: 4. Diljith Das | O21: Best Captain Award(15000) | P21: =15000+6000 -> 21000 | T21: 4. Renjish | U21: Man of the match(5000): 1 | V21: 8000 | X21: 100 | Y21: 0.5 | Z21: =Y21*1500 -> 750 | AA21: =Y21*60 -> 30
A22: 14. Renjish | B22: Level 1 Stadiums | C22: Home (Italy): 5000 bet (Lost) | E22: 14. Unity T20 Cup (Home) | F22: 13. Dileep from PNG: 15000 | G22: Most sixes: 1 | H22: Prediction Winners: 20000 | J22: Away (Bangladesh): 5000 bet (Won) | O22: Team of the tournament(Captain) - 6000 | U22: Best Batsman(3000): 1 | X22: CPL | Y22: 2 | Z22: =Y22*1500 -> 3000 | AA22: =Y22*60 -> 120
A23: 15. Sachin P | B23: None | C23: Home (Bangladesh): 10000 bet ( Lost ) | E23: 15. Legacy Cup (Away) | G23: • vs Australia: 300 | J23: Away(UAE): 5000 bet (Lost) | N23: 5. Sunaif | O23: Golden Bat Award(25000) | P23: =25000+5400 -> 30400 | T23: 5. Rahees | U23: Best Bowler(3000): 1 | V23: 3000 | X23: Total Credits | Z23: =Z19+Z21+Z22 -> 5750 | AA23: =AA19+AA21+AA22 -> 190
A24: 16. Safeer Babu | C24: Away (Pakistan): 5000 bet (Won) | E24: 16. Royal Rivalry Cup (Home) | G24: 3. Toby | J24: Away(Netherlands): 10000 (Lost) | O24: Team of the tournament - 5400 | T24: 6. Diljith Das | U24: Man of the match(5000): 1 | V24: 8000 | W24: 3. Jyothish | X24: Club Series | Y24: 17.5 | Z24: =Y24*1000 -> 17500 | AA24: =Y24*20 -> 350
A25: 17. Sanoop | C25: Home (West Indies): 5000 bet (Won) | E25: 17. Crown & Pearl (Home) | G25: Man of the match: 2 | J25: Home(Scotland): 10000 (Lost) | N25: Champions | P25: 300000 | U25: Best Bowler(3000): 1 | X25: Club Tournament | Y25: 4 | Z25: =Y25*2000 -> 8000 | AA25: =Y25*20 -> 80
A26: 18. Sri Vishnu | C26: Away (Netherlands): 4000 bet (Won) | E26: 18. ODI WC Warmup 5 (Home) | G26: • vs Afghanistan: 500 | T26: 7. Ajin | U26: Best Batsman(3000): 1 | V26: 3000 | X26: T10 Series | Y26: 7.5 | Z26: =Y26*2000 -> 15000 | AA26: =Y26*40 -> 300
A27: 19. Sunaif | C27: Home(Bangladesh): 5000 bet(Lost) | E27: 19. Kingstown Cup (Away) | F27: Player limit exceeded: | G27: • vs South Africa: 500 | I27: Players Awards & Credits | T27: 8. Sanoop | U27: Most Sixes(1000): 1 | V27: 1000 | X27: T20 Series | Y27: 20 | Z27: =Y27*3000 -> 60000 | AA27: =Y27*40 -> 800
C28: Away (Netherlands): 5000 bet (Lost) | F28: -10000 | G28: Economical bowler: 3 | I28: Player | J28: Award | K28: Credits | T28: Semifinalists | V28: 1000000 | X28: ODI Series | Y28: 7 | Z28: =Y28*5000 -> 35000 | AA28: =Y28*100 -> 700
C29: Home(Srilanka): 5000 bet (Lost) | E29: IOCF LONE WARRIOR | F29: 1. 20 to 25: 10000 | G29: • vs Scotland: 300 | I29: 1. Aneesh | J29: Man of the Match: 0 (1000) | K29: 500 | X29: T20 Tournament | Y29: 4.5 | Z29: =Y29*6000 -> 27000 | AA29: =Y29*40 -> 180
C30: Home(UAE): 5000 bet (Won) | E30: 40000 | G30: • vs South Africa: 300 | J30: Best Batsman: 1 (500) | X30: Test Tournament | Y30: 17 | Z30: =Y30*8000 -> 136000 | AA30: =Y30*80 -> 1360
C31: Away(Australia): 10000 bet (Lost) | E31: Champion: Diljith Das | G31: • vs Scotland(Final): 500 | J31: Best Bowler: 0 (500) | X31: ODI Tournament | Y31: 7 | Z31: =Y31*10000 -> 70000 | AA31: =Y31*100 -> 700
C32: Home(Newzealand): 10000 bet (Won) | G32: 4. Rejith | I32: 2. Jyothish S | J32: Man of the Match: 4 (1000) | K32: 6000 | X32: Test Series | Y32: 2.5 | Z32: =Y32*4000 -> 10000 | AA32: =Y32*80 -> 200
C33: Home(Bangladesh): 5000 bet(Won) | E33: IOCF HALL OF FAME | F33: Sponsors | G33: Man of the match: 2 | J33: Best Batsman: 0 (500) | X33: Franchise League
C34: Home(Bangladesh): 5000 bet (Won) | E34: 100000 | F34: 300000 | G34: • vs West Indies: 500 | J34: Best Bowler: 4 (500) | X34: 100 | Y34: 3 | Z34: =Y34*1500 -> 4500 | AA34: =Y34*60 -> 180
C35: Home(Bangladesh): 5000 bet (Lost) | E35: Molly Stephan | F35: 1. Cricket Circle (Title Sponsors) | G35: • vs Newzealand: 500 | I35: 3. Toby Joseph | J35: Man of the Match: 0 (1000) | K35: 500 | X35: PSL | Y35: 4 | Z35: =Y35*1500 -> 6000 | AA35: =Y35*60 -> 240
C36: Home(UAE): 5000 bet (Lost) | E36: Ring of Fire : Top Scorer | F36: 2. S-Mark SportsWear (Kit Sponsors) | G36: Most sixes: 1 | J36: Best Batsman: 1 (500) | X36: KCL | Y36: 3 | Z36: =Y36*1500 -> 4500 | AA36: =Y36*60 -> 180
C37: Away(Australia): 10000 bet (Won) | E37: Jyothish S | F37: 3. Brand Sports ( Merchandise Sponsor ) | G37: • vs West Indies: 300 | J37: Best Bowler: 0 (500) | X37: IPL | Y37: 5 | Z37: =Y37*1500 -> 7500 | AA37: =Y37*60 -> 300
C38: Home(India): 10000 bet (Won) | E38: Ring of Fire : Top Wicket Taker | G38: • vs Newzealand: 300 | I38: 4. Safeer Babu | J38: Man of the Match: 1 (1000) | K38: 2000 | X38: BBL | Y38: 2 | Z38: =Y38*1500 -> 3000 | AA38: =Y38*60 -> 120
C39: Home(South Africa): 5000 (Won) | G39: 5. Achuz | J39: Best Batsman: 0 (500) | X39: CPL | Y39: 4 | Z39: =Y39*1500 -> 6000 | AA39: =Y39*60 -> 240
C40: Home(Uganda): 5000 (Won) | G40: Man of the match: 1 | J40: Best Bowler: 2 (500) | X40: Total Credits | Z40: =Z24+Z25+Z26+Z27+Z28+Z29+Z30+Z34+Z35+Z36+Z37+Z38+Z39+Z31+Z32 -> 410000 | AA40: =AA24+AA25+AA26+AA27+AA28+AA29+AA30+AA34+AA35+AA36+AA37+AA38+AA39+AA31+AA32 -> 5930
...

Sheet India
A1: Board: INDIA
A2: Chairman: Shivaji Prakash | CEO: Jana CP
A3: Credits left:
A4: =100000+B6+C6+D6+E6+F6+G6+A53+C24+F12+J6+P6+M6 -> 3852710
A5: Players | B5: Stadium: | C5: International Series: | D5: Whitewash: | E5: IOCF T20 WORLD CUP 🏆: | F5: Player limit Increased: | G5: IOCF WORLD TEST CHAMPIONSHIP 🏆: | J5: CONTINENTAL CUP 2026 🏆: ( ASIA ) | M5: ODI WORLD 2026 🏆: | P5: Umpires Credits :
A6: 1. Abheshek | B6: -170000 | C6: 17000 | D6: 1000 | E6: 35000 | F6: -10000 | G6: =G8+H8+I8 -> -500 | J6: =J8 -> 21800 | M6: =M8 -> 846000 | P6: =S16+S19+S23+S26+S29+S33+S36+S39 -> 145750
A7: 2. Abin | B7: Level 3 Stadiums | C7: Away( England ): 5000 bet ( Won ) | D7: 1. Anderson Tendulkar ( England ) | E7: Entry: -5000 | F7: 1. 20 to 25: 10000 | G7: Player Awards | H7: Match Bet Credits | I7: Entry Credits | J7: Players & Match Awards | M7: Players & Match Awards | P7: Umpire | Q7: Details | R7: Total Matches | S7: Credits | T7: Points
A8: 3. Ajith | B8: Eternal Coliseum | C8: Away( Srilanka): 6000 bet ( Lost ) | E8: Players Awards: 5000 | G8: =I21+I24+I27+I30+I33+I36 -> 9000 | H8: -4500 | I8: -5000 | J8: =L10+L13+L15+L16 -> 21800 | M8: =O10+O15+O17+O20+O21+O22+O23 -> 846000 | P8: 1. Shivaji Prakash | Q8: Club Series | R8: 18 | S8: =R8*1000 -> 18000 | T8: =R8*20 -> 360
A9: 4. Anshad P | B9: Sree Padmanaba Cricket Park | C9: Home ( England): 10000 ( Lost ) | E9: 1. Anshad | H9: Away (Afghanistan): 7000 bet (Lost) | I9: Trophy Cabinet (Test) | J9: Player | K9: Award | L9: Credits | M9: Player | N9: Award | O9: Credits | Q9: T10 Series | R9: 5 | S9: =R9*2000 -> 10000 | T9: =R9*40 -> 200
A10: 5. Asish Anandhu | B10: Jannat Wadi | Franchise League L1 | Upgraded | C10: Away (Netherlands): 2000 (Lost) | E10: Man of the match: 1 | H10: Away(Netherlands): 2500 bet (Won) | I10: 1. Zubeen Garg Rhine A | J10: 1. Shivaji Prakash | K10: Best Batsman(1000): 1 | L10: =2000+5400 -> 7400 | M10: 1. Shivaji Prakash | N10: Man of the match(5000): 2 | O10: 324000 | Q10: Test Tournament | R10: 3 | S10: =R10*8000 -> 24000 | T10: =R10*80 -> 240
A11: 6. Asru | B11: Level 2 Stadiums | C11: Away(Australia): 5000 (Won) | E11: • vs Pakistan: 500 | F11: Players Trade | H11: Away (England): 5000 bet (Lost) | I11: 2. Legacy Trophy | K11: Best Bowler(1000): 1 | N11: Best Bowler(3000): 2 | Q11: ODI Tournament | R11: 3 | S11: =R11*10000 -> 30000 | T11: =R11*80 -> 240
A12: 7. Aswin Babu | B12: None | C12: Home(Australia): 5000 (Lost) | E12: Economical Bowler: 2 | F12: -270000 | H12: Home (Pakistan): 5000 bet (Won) | I12: 3. Border-Gavaskar Test | K12: Team of the tournament - 5400 | N12: Most Sixes(1000): 2 | Q12: Franchise League
A13: 8. Athif Basheer K | B13: Level 1 Stadiums | C13: Away(England): 10000 (Lost) | E13: • vs Pakistan: 300 | F13: 1. Ajith from NZ: 10000 | H13: Away(South Africa): 5000 bet (Lost) | I13: 4. Italia–Bharat Test | J13: 2. Asru KSD | K13: Man of the match(2000): 2 | L13: 6000 | N13: Most Dot Balls(1000): 6 | Q13: KCL | R13: 1 | S13: =R13*1500 -> 1500 | T13: =R13*60 -> 60
A14: 9. Farhaan | B14: Prince's Arena | C14: Away(UAE): 5000 (Lost) | E14: • vs Newzealand: 300 | F14: 2. Mowglee from WI: 100000 | H14: Home(South Africa): 5000 bet (Lost) | K14: Best Bowler(1000): 2 | N14: Most Dot Balls in the Tournament: 300000 | Q14: IPL | R14: 9 | S14: =R14*1500 -> 13500 | T14: =R14*60 -> 540
A15: 10. George | B15: Lion's Citadel | C15: Home(UAE): 5000 (Lost) | E15: 2. Raheem | F15: 3. George from WI: 100000 | H15: Home(Italy): 10000 bet (Lost) | J15: 3. Anshad P | K15: Best Batsman(1000): 1 | L15: 1000 | M15: 2. Farhan | N15: Best Batsman(3000): 1 | O15: 4000 | Q15: CPL | R15: 1 | S15: =R15*1500 -> 1500 | T15: =R15*60 -> 60
A16: 11. Gopikrishnan SV | B16: Master's Arena | C16: Away(England): 5000 (Lost) | D16: Trophy Cabinet | E16: Most Sixes: 1 | F16: 4. Aswin from USA: 60000 | H16: Away(Australia): 10000 bet (Won) | J16: 4. Jana CP | K16: Man of the match(2000): 1 | L16: =2000+5400 -> 7400 | N16: Most Sixes(1000): 1 | Q16: Total Credits | S16: =S8+S9+S10+S13+S14+S15+S11 -> 98500 | T16: =T8+T9+T10+T13+T14+T15+T11 -> 1700
A17: 12. Harish Byndoor | B17: King's Fortress | C17: Away(Australia): 5000 (Lost) | D17: 1. Coca Cola Cup | E17: • vs Pakistan: 300 | H17: Away(Italy): 10000 (Won) | K17: Team of the tournament - 5400 | M17: 3. Anshad Parakkadan | N17: Man of the match(5000): 1 | O17: 9000 | P17: 2. Jana CP | Q17: Franchise League
A18: 13. Mowglee | B18: Marusthal Arena | C18: Home(West Indies): 10000 (Won) | D18: 2. India - Carribbean Showdown Series(Home) | E18: 3. Shivaji Prakash | N18: Best Bowler(3000): 1 | Q18: IPL | R18: 4.5 | S18: =R18*1500 -> 6750 | T18: =R18*60 -> 270
A19: 14. Peter John | B19: Imperial Stadium | C19: Home(West Indies): 10000 (Won) | D19: 3. India - Caribbean ODI Showdown Series (Home) | E19: Man of the match: 1 | G19: Players Awards & Credits | N19: Most Sixes(1000): 1 | Q19: Total Credits | S19: =S18 -> 6750 | T19: =T18 -> 270
A20: 15. Pradeesh P | B20: Dwarka Coliseum | C20: Away(India): 10000 (Won) | D20: 4. Anderson-Tendulker t20 trophy (Away) | E20: • vs Srilanka: 500 | G20: Player | H20: Award | I20: Credits | M20: 4. Jana CP | N20: Most Dot Balls(1000): 1 | O20: 1000 | P20: 3. Abhishek | Q20: Franchise League
A21: 16. Raheem K | B21: Royal Deccan | C21: Away(UAE): 10000 (Won) | D21: 5. TITANS Cup (Away) | E21: Economical bowler: 2 | G21: 1. Rahul Seenu | H21: Man of the Match: 0 (1000) | I21: 500 | M21: 5. Peter John | N21: Man of the match(5000): 1 | O21: 5000 | Q21: IPL | R21: 5 | S21: =R21*1500 -> 7500 | T21: =R21*60 -> 300
A22: 17. Rahman SN | B22: Eternal Aryavarta | C22: Away(Newzealand): 10000 (Lost) | E22: • vs South Africa: 300 | H22: Best Batsman: 0 (500) | M22: 6. Asru MSD | N22: Best Bowler(3000): 1 | O22: 3000 | Q22: CPL | R22: 2 | S22: =R22*1500 -> 3000 | T22: =R22*60 -> 120
A23: 18. Rahul Roy | B23: Sher-E-Punjab | C23: IOCF LONE WARRIOR | E23: • vs Scotland(Semis): 300 | H23: Best Bowler: 1 (500) | M23: Quarterfinalists | O23: 500000 | Q23: Total Credits | S23: =S21+S22 -> 10500 | T23: =T21+T22 -> 420
A24: 19. Rahul Seenu | C24: 10000 | E24: Most Sixes: 1 | G24: 2. Farhan | H24: Man of the Match: 1 (1000) | I24: 2000 | P24: 4. Athif Basheer | Q24: Franchise League
A25: 20. Rajeev | C25: Semifinalit: Anshad | E25: • vs Newzealand: 300 | H25: Best Batsman: 2 (500) | Q25: IPL | R25: 4 | S25: =R25*1500 -> 6000 | T25: =R25*60 -> 240
A26: 21. Robert John | E26: 4. Pradeesh | H26: Best Bowler: 0 (500) | Q26: Total Credits | S26: =S25 -> 6000 | T26: =T25 -> 240
A27: 22. Sanjith | E27: Economical Bowler: 1 | G27: 3. Jana | H27: Man of the Match: 2 (1000) | I27: 4000 | P27: 5. Robert John | Q27: Franchise League
A28: 21. Niyas | E28: • vs Srilanka: 300 | H28: Best Batsman: 2 (500) | Q28: IPL | R28: 3 | S28: =R28*1500 -> 4500 | T28: =R28*60 -> 180
A29: 22. Mashoo | E29: 5. Jana | H29: Best Bowler: 2 (500) | Q29: Total Credits | S29: =S28 -> 4500 | T29: =T28 -> 180
A30: 23. Zachu | E30: Man of the match: 1 | G30: 4. Asru | H30: Man of the Match: 1 (1000) | I30: 1500 | P30: 6. Farhan | Q30: Franchise League
A31: 24. Achu RVD | E31: • vs South Africa: 500 | H31: Best Batsman: 1 (500) | Q31: IPL | R31: 3 | S31: =R31*1500 -> 4500 | T31: =R31*60 -> 180
E32: 6. Abin | H32: Best Bowler: 0 (500) | Q32: IPL ( Commentator ) | R32: 1 | S32: =R32*1500 -> 1500 | T32: =R32*60 -> 60
E33: Most Sixes: 1 | G33: 5. Shivaji Prakash | H33: Man of the Match: 0 (1000) | I33: 500 | Q33: Total Credits | S33: =S31+S32 -> 6000 | T33: =T31+T32 -> 240
E34: • vs South Africa: 300 | H34: Best Batsman: 0 (500) | P34: 7. Gopikrishnan | Q34: Franchise League
E35: 7. Farhaan | H35: Best Bowler: 1 (500) | Q35: IPL ( Commentator ) | R35: 1 | S35: =R35*1500 -> 1500 | T35: =R35*60 -> 60
E36: Man of the match: 1 | G36: 6. Pradeesh P Nair | H36: Man of the Match: 0 (1000) | I36: 500 | Q36: Total Credits | S36: =S35 -> 1500 | T36: =T35 -> 60
E37: • vs England: 500 | H37: Best Batsman: 0 (500) | P37: 8. Mowglee | Q37: T10 Series | R37: 1 | S37: =R37*2000 -> 2000 | T37: =R37*40 -> 40
E38: Most Sixes: 1 | H38: Best Bowler: 1 (500) | Q38: ODI Tournament | R38: 1 | S38: =R38*10000 -> 10000 | T38: =R38*80 -> 80
E39: • vs England: 300 | Q39: Total Credits | S39: =S38+S37 -> 12000 | T39: =T38+T37 -> 120
E40: 8. Gopi SV
...

Sheet Ireland
A1: Board: Ireland
A2: Chairman: Ali Abbas Bangash | CEO: Sunny
A3: CLOTHING SPONSORS: VYLAX Clothing
A4: Credits left:
A5: =100000+B7+C7+E7+F7+F15+A30+G7+L7+B16 -> 718775
A6: Players | B6: Traded Player: | C6: Stadium: | D6: Trophy Cabinet | E6: International Series: | F6: Whitewash Win: | G6: Umpires Credits : | L6: Associate Nations CUP 2026 🏆:
A7: 1. Abhishek | B7: 47000 | C7: -60000 | D7: 1. The Green & Gold Derby( Home) | E7: 30000 | F7: 1000 | G7: =J15 -> 43000 | L7: =L9 -> 225000
A8: 2. Akshay | B8: 1. Arjun from Aus: 7000 | C8: Level 3 Stadiums | D8: 2. Sukumara Kurup Memorial Trophy (Away) | E8: Home(Zimbabwe): 3000 (Won) | F8: Against Zimbabwe: 1 | G8: Umpire | H8: Details | I8: Total Matches | J8: Credits | K8: Points | L8: Players & Match Awards
A9: 3. Alan Aji | B9: 2. Biswajit from Ned: 10000 | C9: The Village | D9: 3. Ire-Zim Clash (Home) | E9: Away(USA): 5000 (Lost) | G9: 1. Ali Abbas | H9: Club Tournament | I9: 1 | J9: =I9*2000 -> 2000 | K9: =I9*20 -> 20 | L9: =N11+N13+N15+N17+N19+N20+N21 -> 225000
A10: 4. Athulnath | B10: 3. Sayandeep (Chairman Argentina): 10k | C10: Pareed Storziwal Sports Arena | D10: 4. ODI WC Warmup 7 (Home) | E10: Away(Uganda): 5000 (Won) | H10: Test Series | I10: 1 | J10: =I10*4000 -> 4000 | K10: =I10*80 -> 80 | L10: Player | M10: Award | N10: Credits
A11: 5. Fakhar Abbas Bangash | B11: 4. Arsal (Chairman Nepal): 10k | C11: Level 2 Stadiums | D11: 5. Emerald & Stars Trophy (Home) | E11: Home (Australia): 6000 (Lost) | H11: Test Tournament | I11: 2 | J11: =I11*8000 -> 16000 | K11: =I11*80 -> 160 | L11: 1. Ali Abbas Bangash | M11: Man of the match (2000): 1 | N11: 4000
A12: 6. Huzaifa | B12: 5. Seru (Chairman Japan): 10k | C12: None | D12: 6. Irish-Caribbean Challenge (Home) | E12: Home(Zimbabwe): 5000 (Won) | H12: T10 Series | I12: 7 | J12: =I12*2000 -> 14000 | K12: =I12*40 -> 280 | M12: Best Bowler (1000): 2
A13: 7. Karthik Varma | C13: Level 1 Stadiums | D13: 7. Emerald - Dutch Trophy (Home) | E13: Away(Qatar): 5000 (Lost) | H13: Club Series | I13: 1 | J13: =I13*1000 -> 1000 | K13: =I13*20 -> 20 | L13: 2. Rahim Ullah | M13: Man of the match (2000): 2 | N13: 6000
A14: 8. Kranthi Smith | C14: None | D14: 8. RED & GREEN RIVALRY I (Home) | E14: Home(Pakistan): 5000 (Won) | F14: Whitewash lose: | H14: T20 Series | I14: 2 | J14: =I14*3000 -> 6000 | K14: =I14*40 -> 80 | M14: Best Bowler (1000): 2
A15: 9. Noufal | B15: Sponsors | E15: Home(USA): 5000 (Won) | F15: -500 | H15: Total Credits | J15: =J9+J10+J11+J12+J13+J14 -> 43000 | K15: =K9+K10+K11+K12+K13+K14 -> 640 | L15: 3. Noufal | M15: Best Batsman(1000): 1 | N15: 11000
